{"isSuccess":true,"url":"http://rosettacode.org//wiki/Exceptions/Catch_an_exception_thrown_in_a_nested_call","codeArray":["function U() {}\nU.prototype.toString = function() {\n    return this.className;\n}\n\nfunction U0() {\n    this.className = arguments.callee.name;\n}\nU0.prototype = new U();\n\nfunction U1() {\n    this.className = arguments.callee.name;\n}\nU1.prototype = new U();\n\nfunction foo() {\n    for (var i = 1; i <= 2; i++) {\n        try {\n            bar();\n        } catch (e\n            if e instanceof U0) {\n            print(\"caught exception \" + e);\n        }\n    }\n}\n\nfunction bar() {\n    baz();\n}\n\nfunction baz() {\n    // during the first call, redefine the function for subsequent calls\n    baz = function() {\n        throw (new U1());\n    }\n    throw (new U0());\n}\nfoo();"],"uncertainCodeArray":[],"textArray":[]}