{"isSuccess":true,"url":"http://rosettacode.org//wiki/Exceptions/Catch_an_exception_thrown_in_a_nested_call","codeArray":["function U() {}\n  U.prototype.toString = function(){return this.className;}\n  function U0() { \n      this.className = arguments.callee.name; \n  }\n  U0.prototype = new U();\n  function U1() {\n      this.className = arguments.callee.name; \n  }\n  U1.prototype = new U();\n  function foo() {\n      for (var i = 1; i <= 2; i++) {\n          try {\n              bar();\n          }\n          catch(e if e instanceof U0) {\n              print(\"caught exception \" + e);\n          }\n      }\n  }\n  function bar() {\n      baz();\n  }\n  function baz() {\n      // during the first call, redefine the function for subsequent calls\n      baz = function() {throw(new U1());}\n      throw(new U0());\n  }\n  foo();"],"uncertainCodeArray":[],"textArray":[]}